ERROR:root:US1NMRA0022: 
Traceback (most recent call last):
  File "ghcn_multiprocessing.py", line 1736, in parse_to_netCDF
    'station_name', 'S1', ('station', 'station_name_to_char',))[:] = netCDF4.stringtochar(np.array([self.stationLongNameDict[fileId]], 'S'+str(len(self.stationLongNameDict[fileId].strip()))))
  File "utils.pyx", line 66, in netCDF4.stringtochar (netCDF4.c:3452)
ValueError: setting an array element with a sequence
ERROR:root:USC00265440: 
Traceback (most recent call last):
  File "ghcn_multiprocessing.py", line 1917, in parse_to_netCDF
    ds.comment = 'Data was converted from native fixed-length text (DLY) format to NetCDF-4 format following metadata conventions.'
  File "netCDF4.pyx", line 1498, in netCDF4.Dataset.__exit__ (netCDF4.c:20165)
  File "netCDF4.pyx", line 1554, in netCDF4.Dataset.close (netCDF4.c:21176)
RuntimeError: NetCDF: HDF error
ERROR:root:USC00314675: 
Traceback (most recent call last):
  File "ghcn_multiprocessing.py", line 1917, in parse_to_netCDF
    ds.comment = 'Data was converted from native fixed-length text (DLY) format to NetCDF-4 format following metadata conventions.'
  File "netCDF4.pyx", line 1498, in netCDF4.Dataset.__exit__ (netCDF4.c:20165)
  File "netCDF4.pyx", line 1554, in netCDF4.Dataset.close (netCDF4.c:21176)
RuntimeError: NetCDF: HDF error
ERROR:root:SF003670660: 
Traceback (most recent call last):
  File "ghcn_multiprocessing.py", line 1917, in parse_to_netCDF
    ds.comment = 'Data was converted from native fixed-length text (DLY) format to NetCDF-4 format following metadata conventions.'
  File "netCDF4.pyx", line 1498, in netCDF4.Dataset.__exit__ (netCDF4.c:20165)
  File "netCDF4.pyx", line 1554, in netCDF4.Dataset.close (netCDF4.c:21176)
RuntimeError: NetCDF: HDF error
ERROR:root:USC00415828: 
Traceback (most recent call last):
  File "ghcn_multiprocessing.py", line 1917, in parse_to_netCDF
    ds.comment = 'Data was converted from native fixed-length text (DLY) format to NetCDF-4 format following metadata conventions.'
  File "netCDF4.pyx", line 1498, in netCDF4.Dataset.__exit__ (netCDF4.c:20165)
  File "netCDF4.pyx", line 1554, in netCDF4.Dataset.close (netCDF4.c:21176)
RuntimeError: NetCDF: HDF error
ERROR:root:USC00517711: 
Traceback (most recent call last):
  File "ghcn_multiprocessing.py", line 1917, in parse_to_netCDF
    ds.comment = 'Data was converted from native fixed-length text (DLY) format to NetCDF-4 format following metadata conventions.'
  File "netCDF4.pyx", line 1498, in netCDF4.Dataset.__exit__ (netCDF4.c:20165)
  File "netCDF4.pyx", line 1554, in netCDF4.Dataset.close (netCDF4.c:21176)
RuntimeError: NetCDF: HDF error
ERROR:root:USC00143822: 
Traceback (most recent call last):
  File "ghcn_multiprocessing.py", line 1917, in parse_to_netCDF
    ds.comment = 'Data was converted from native fixed-length text (DLY) format to NetCDF-4 format following metadata conventions.'
  File "netCDF4.pyx", line 1498, in netCDF4.Dataset.__exit__ (netCDF4.c:20165)
  File "netCDF4.pyx", line 1554, in netCDF4.Dataset.close (netCDF4.c:21176)
RuntimeError: NetCDF: HDF error
ERROR:root:USC00235121: 
Traceback (most recent call last):
  File "ghcn_multiprocessing.py", line 1917, in parse_to_netCDF
    ds.comment = 'Data was converted from native fixed-length text (DLY) format to NetCDF-4 format following metadata conventions.'
  File "netCDF4.pyx", line 1498, in netCDF4.Dataset.__exit__ (netCDF4.c:20165)
  File "netCDF4.pyx", line 1554, in netCDF4.Dataset.close (netCDF4.c:21176)
RuntimeError: NetCDF: HDF error
ERROR:root:USC00035354: 
Traceback (most recent call last):
  File "ghcn_multiprocessing.py", line 1917, in parse_to_netCDF
    ds.comment = 'Data was converted from native fixed-length text (DLY) format to NetCDF-4 format following metadata conventions.'
  File "netCDF4.pyx", line 1498, in netCDF4.Dataset.__exit__ (netCDF4.c:20165)
  File "netCDF4.pyx", line 1554, in netCDF4.Dataset.close (netCDF4.c:21176)
RuntimeError: NetCDF: HDF error
ERROR:root:USC00391739: 
Traceback (most recent call last):
  File "ghcn_multiprocessing.py", line 1917, in parse_to_netCDF
    ds.comment = 'Data was converted from native fixed-length text (DLY) format to NetCDF-4 format following metadata conventions.'
  File "netCDF4.pyx", line 1498, in netCDF4.Dataset.__exit__ (netCDF4.c:20165)
  File "netCDF4.pyx", line 1554, in netCDF4.Dataset.close (netCDF4.c:21176)
RuntimeError: NetCDF: HDF error
ERROR:root:USC00481610: 
Traceback (most recent call last):
  File "ghcn_multiprocessing.py", line 1917, in parse_to_netCDF
    ds.comment = 'Data was converted from native fixed-length text (DLY) format to NetCDF-4 format following metadata conventions.'
  File "netCDF4.pyx", line 1498, in netCDF4.Dataset.__exit__ (netCDF4.c:20165)
  File "netCDF4.pyx", line 1554, in netCDF4.Dataset.close (netCDF4.c:21176)
RuntimeError: NetCDF: HDF error
ERROR:root:USC00112931: 
Traceback (most recent call last):
  File "ghcn_multiprocessing.py", line 1917, in parse_to_netCDF
    ds.comment = 'Data was converted from native fixed-length text (DLY) format to NetCDF-4 format following metadata conventions.'
  File "netCDF4.pyx", line 1498, in netCDF4.Dataset.__exit__ (netCDF4.c:20165)
  File "netCDF4.pyx", line 1554, in netCDF4.Dataset.close (netCDF4.c:21176)
RuntimeError: NetCDF: HDF error
ERROR:root:USC00347390: 
Traceback (most recent call last):
  File "ghcn_multiprocessing.py", line 1917, in parse_to_netCDF
    ds.comment = 'Data was converted from native fixed-length text (DLY) format to NetCDF-4 format following metadata conventions.'
  File "netCDF4.pyx", line 1498, in netCDF4.Dataset.__exit__ (netCDF4.c:20165)
  File "netCDF4.pyx", line 1554, in netCDF4.Dataset.close (netCDF4.c:21176)
RuntimeError: NetCDF: HDF error
ERROR:root:USC00452914: 
Traceback (most recent call last):
  File "ghcn_multiprocessing.py", line 1917, in parse_to_netCDF
    ds.comment = 'Data was converted from native fixed-length text (DLY) format to NetCDF-4 format following metadata conventions.'
  File "netCDF4.pyx", line 1498, in netCDF4.Dataset.__exit__ (netCDF4.c:20165)
  File "netCDF4.pyx", line 1554, in netCDF4.Dataset.close (netCDF4.c:21176)
RuntimeError: NetCDF: HDF error
ERROR:root:USC00053867: 
Traceback (most recent call last):
  File "ghcn_multiprocessing.py", line 1917, in parse_to_netCDF
    ds.comment = 'Data was converted from native fixed-length text (DLY) format to NetCDF-4 format following metadata conventions.'
  File "netCDF4.pyx", line 1498, in netCDF4.Dataset.__exit__ (netCDF4.c:20165)
  File "netCDF4.pyx", line 1554, in netCDF4.Dataset.close (netCDF4.c:21176)
RuntimeError: NetCDF: HDF error
ERROR:root:USC00204502: 
Traceback (most recent call last):
  File "ghcn_multiprocessing.py", line 1917, in parse_to_netCDF
    ds.comment = 'Data was converted from native fixed-length text (DLY) format to NetCDF-4 format following metadata conventions.'
  File "netCDF4.pyx", line 1498, in netCDF4.Dataset.__exit__ (netCDF4.c:20165)
  File "netCDF4.pyx", line 1554, in netCDF4.Dataset.close (netCDF4.c:21176)
RuntimeError: NetCDF: HDF error
ERROR:root:SF003671770: 
Traceback (most recent call last):
  File "ghcn_multiprocessing.py", line 1917, in parse_to_netCDF
    ds.comment = 'Data was converted from native fixed-length text (DLY) format to NetCDF-4 format following metadata conventions.'
  File "netCDF4.pyx", line 1498, in netCDF4.Dataset.__exit__ (netCDF4.c:20165)
  File "netCDF4.pyx", line 1554, in netCDF4.Dataset.close (netCDF4.c:21176)
RuntimeError: NetCDF: HDF error
ERROR:root:USC00204534: 
Traceback (most recent call last):
  File "ghcn_multiprocessing.py", line 1917, in parse_to_netCDF
    ds.comment = 'Data was converted from native fixed-length text (DLY) format to NetCDF-4 format following metadata conventions.'
  File "netCDF4.pyx", line 1498, in netCDF4.Dataset.__exit__ (netCDF4.c:20165)
  File "netCDF4.pyx", line 1554, in netCDF4.Dataset.close (netCDF4.c:21176)
RuntimeError: NetCDF: HDF error
ERROR:root:USC00265441: 
Traceback (most recent call last):
  File "ghcn_multiprocessing.py", line 1917, in parse_to_netCDF
    ds.comment = 'Data was converted from native fixed-length text (DLY) format to NetCDF-4 format following metadata conventions.'
  File "netCDF4.pyx", line 1498, in netCDF4.Dataset.__exit__ (netCDF4.c:20165)
  File "netCDF4.pyx", line 1554, in netCDF4.Dataset.close (netCDF4.c:21176)
RuntimeError: NetCDF: HDF error
ERROR:root:USC00314679: 
Traceback (most recent call last):
  File "ghcn_multiprocessing.py", line 1917, in parse_to_netCDF
    ds.comment = 'Data was converted from native fixed-length text (DLY) format to NetCDF-4 format following metadata conventions.'
  File "netCDF4.pyx", line 1498, in netCDF4.Dataset.__exit__ (netCDF4.c:20165)
  File "netCDF4.pyx", line 1554, in netCDF4.Dataset.close (netCDF4.c:21176)
RuntimeError: NetCDF: HDF error
ERROR:root:USC00235130: 
Traceback (most recent call last):
  File "ghcn_multiprocessing.py", line 1917, in parse_to_netCDF
    ds.comment = 'Data was converted from native fixed-length text (DLY) format to NetCDF-4 format following metadata conventions.'
  File "netCDF4.pyx", line 1498, in netCDF4.Dataset.__exit__ (netCDF4.c:20165)
  File "netCDF4.pyx", line 1554, in netCDF4.Dataset.close (netCDF4.c:21176)
RuntimeError: NetCDF: HDF error
ERROR:root:USC00112958: 
Traceback (most recent call last):
  File "ghcn_multiprocessing.py", line 1917, in parse_to_netCDF
    ds.comment = 'Data was converted from native fixed-length text (DLY) format to NetCDF-4 format following metadata conventions.'
  File "netCDF4.pyx", line 1498, in netCDF4.Dataset.__exit__ (netCDF4.c:20165)
  File "netCDF4.pyx", line 1554, in netCDF4.Dataset.close (netCDF4.c:21176)
RuntimeError: NetCDF: HDF error
ERROR:root:USC00391740: 
Traceback (most recent call last):
  File "ghcn_multiprocessing.py", line 1917, in parse_to_netCDF
    ds.comment = 'Data was converted from native fixed-length text (DLY) format to NetCDF-4 format following metadata conventions.'
  File "netCDF4.pyx", line 1498, in netCDF4.Dataset.__exit__ (netCDF4.c:20165)
  File "netCDF4.pyx", line 1554, in netCDF4.Dataset.close (netCDF4.c:21176)
RuntimeError: NetCDF: HDF error
ERROR:root:USC00347394: 
Traceback (most recent call last):
  File "ghcn_multiprocessing.py", line 1917, in parse_to_netCDF
    ds.comment = 'Data was converted from native fixed-length text (DLY) format to NetCDF-4 format following metadata conventions.'
  File "netCDF4.pyx", line 1498, in netCDF4.Dataset.__exit__ (netCDF4.c:20165)
  File "netCDF4.pyx", line 1554, in netCDF4.Dataset.close (netCDF4.c:21176)
RuntimeError: NetCDF: HDF error
ERROR:root:USC00415832: 
Traceback (most recent call last):
  File "ghcn_multiprocessing.py", line 1917, in parse_to_netCDF
    ds.comment = 'Data was converted from native fixed-length text (DLY) format to NetCDF-4 format following metadata conventions.'
  File "netCDF4.pyx", line 1498, in netCDF4.Dataset.__exit__ (netCDF4.c:20165)
  File "netCDF4.pyx", line 1554, in netCDF4.Dataset.close (netCDF4.c:21176)
RuntimeError: NetCDF: HDF error
ERROR:root:USC00481670: 
Traceback (most recent call last):
  File "ghcn_multiprocessing.py", line 1917, in parse_to_netCDF
    ds.comment = 'Data was converted from native fixed-length text (DLY) format to NetCDF-4 format following metadata conventions.'
  File "netCDF4.pyx", line 1498, in netCDF4.Dataset.__exit__ (netCDF4.c:20165)
  File "netCDF4.pyx", line 1554, in netCDF4.Dataset.close (netCDF4.c:21176)
RuntimeError: NetCDF: HDF error
ERROR:root:USC00452950: 
Traceback (most recent call last):
  File "ghcn_multiprocessing.py", line 1917, in parse_to_netCDF
    ds.comment = 'Data was converted from native fixed-length text (DLY) format to NetCDF-4 format following metadata conventions.'
  File "netCDF4.pyx", line 1498, in netCDF4.Dataset.__exit__ (netCDF4.c:20165)
  File "netCDF4.pyx", line 1554, in netCDF4.Dataset.close (netCDF4.c:21176)
RuntimeError: NetCDF: HDF error
ERROR:root:USC00517721: 
Traceback (most recent call last):
  File "ghcn_multiprocessing.py", line 1917, in parse_to_netCDF
    ds.comment = 'Data was converted from native fixed-length text (DLY) format to NetCDF-4 format following metadata conventions.'
  File "netCDF4.pyx", line 1498, in netCDF4.Dataset.__exit__ (netCDF4.c:20165)
  File "netCDF4.pyx", line 1554, in netCDF4.Dataset.close (netCDF4.c:21176)
RuntimeError: NetCDF: HDF error
